Workbook

Sheet Sheet1
B1: EN - 0 - l2 | D1: EN - 8 - l2 | F1: EN - 0 - l1 | H1: EN - 8 - l1 | J1: SVR - 8 - l1
A2: Date | B2: Expected | C2: Actual | D2: Expected | E2: Actual | F2: Expected | G2: Actual | H2: Expected | I2: Actual | J2: Expected | K2: Actual
A3: 42019 | B3: 222.26 | C3: 235.4 | D3: 220.3 | E3: 230
A4: 42020 | B4: 208.65 | C4: 170.9 | D4: 206.87 | E4: 172.8
A5: 42020 | B5: 221.04 | C5: 219.7 | D5: 219.74 | E5: 219.7
A6: 42021 | B6: 213.77 | C6: 240.4 | D6: 213.63 | E6: 192.3 | F6: 214.21 | G6: 192.3 | H6: 215.82 | I6: 192.3
A7: 42022 | B7: 209.59 | C7: 206.4 | D7: 208.72 | E7: 206.4 | F7: 209.83 | G7: 206.4 | H7: 209.31 | I7: 206.4 | J7: 206.45 | K7: 243.3
A8: 42023 | B8: 218.3 | C8: 256.2 | D8: 216.55 | E8: 258.7 | F8: 217.97 | G8: 253.8 | H8: 217.45 | I8: 275.2 | J8: 214.36 | K8: 249.7
A9: 42024 | B9: 231.67 | C9: 225.5 | D9: 221.95 | E9: 226.9 | F9: 232.12 | G9: 226.9 | H9: 230.82 | I9: 226.9 | J9: 228.3 | K9: 226.9
A10: 42024 | B10: 219.77 | C10: 247.5 | D10: 218.66 | E10: 225.9 | F10: 219.88 | G10: 248.4 | H10: 221.42 | I10: 249.7 | J10: 221.09 | K10: 240.9
A11: 42026 | B11: 223.72 | C11: 189.9 | D11: 224.08 | E11: 177 | F11: 224.29 | G11: 189.9 | H11: 226.23 | I11: 213.8 | J11: 224.41 | K11: 213.8
A12: 42027 | B12: 217.08 | C12: 281.3 | D12: 218.38 | E12: 231.8 | F12: 217.73 | G12: 271.5 | H12: 218.36 | I12: 252 | J12: 213.53 | K12: 243.6
A13: 41664 | B13: 221.06 | C13: 213.4 | D13: 222.23 | E13: 194.9 | F13: 221.33 | G13: 205.9 | H13: 220.52 | I13: 227.9 | J13: 217.87 | K13: 173
A14: 41664 | B14: 213.33 | C14: 214.8 | D14: 213.2 | E14: 214.8 | F14: 213.68 | G14: 213.5 | H14: 214.21 | I14: 215.8 | J14: 212.88 | K14: 186.6
A15: 41667 | B15: 222.08 | C15: 207.2 | D15: 220.99 | E15: 208.3 | F15: 223.57 | G15: 202 | H15: 224.09 | I15: 213.8 | J15: 225.3 | K15: 199.6
A16: 41666 | B16: 215.25 | C16: 162.4 | D16: 215.11 | E16: 166.8 | F16: 215.53 | G16: 152.3 | H16: 214.09 | I16: 163.3 | J16: 213.46 | K16: 177.9
A17: 41665 | B17: 197.97 | C17: 249.2 | D17: 194.03 | E17: 270 | F17: 197.97 | G17: 249.2 | H17: 196.54 | I17: 220.7 | J17: 196.54 | K17: 220.7
A18: 41665 | B18: 201.61 | C18: 191.1 | D18: 201.95 | E18: 191.1 | F18: 201.97 | G18: 191.1 | H18: 203.34 | I18: 191.1 | J18: 201.49 | K18: 188.2
B30: =AVERAGE(B3:B18) -> 216.07187 | C30: =AVERAGE(C3:C18) -> 219.45625 | D30: =AVERAGE(D3:D13) -> 217.37364 | E30: =AVERAGE(E3:E13) -> 212.4 | F30: =AVERAGE(F3:F16) -> 219.10364 | G30: =AVERAGE(G3:G16) -> 214.80909 | H30: =AVERAGE(H3:H16) -> 219.30182 | I30: =AVERAGE(I3:I16) -> 221.55455 | J30: =AVERAGE(J3:J13) -> 218.00143 | K30: =AVERAGE(K3:K13) -> 227.31429
B31: =STDEV(B3:B18) -> 8.5354986 | C31: =STDEV(C3:C18) -> 31.880129 | D31: =STDEV(D3:D10) -> 5.5667168 | E31: =STDEV(E3:E10) -> 26.096329 | F31: =STDEV(F3:F16) -> 6.1411616 | G31: =STDEV(G3:G16) -> 33.703218 | H31: =STDEV(H3:H10) -> 7.9368338 | I31: =STDEV(I3:I10) -> 33.237554 | J31: =STDEV(J3:J10) -> 9.3359556 | K31: =STDEV(K3:K10) -> 9.6131854

Sheet Sheet5
V2: 140 | W2: =_xlfn.NORM.DIST(V2,Sheet4!$J$2,Sheet4!$J$3,FALSE) -> 0.00058339438
A3: Count of score | V3: 150 | W3: =_xlfn.NORM.DIST(V3,Sheet4!$J$2,Sheet4!$J$3,FALSE) -> 0.0012671421
A4: Row Labels | B4: Total | V4: 160 | W4: =_xlfn.NORM.DIST(V4,Sheet4!$J$2,Sheet4!$J$3,FALSE) -> 0.0024643087
A5: 140 | B5: 1 | V5: 170 | W5: =_xlfn.NORM.DIST(V5,Sheet4!$J$2,Sheet4!$J$3,FALSE) -> 0.0042911298
A6: 150 | B6: 5 | V6: 180 | W6: =_xlfn.NORM.DIST(V6,Sheet4!$J$2,Sheet4!$J$3,FALSE) -> 0.0066904437
A7: 160 | B7: 8 | V7: 190 | W7: =_xlfn.NORM.DIST(V7,Sheet4!$J$2,Sheet4!$J$3,FALSE) -> 0.0093399581
A8: 170 | B8: 16 | V8: 200 | W8: =_xlfn.NORM.DIST(V8,Sheet4!$J$2,Sheet4!$J$3,FALSE) -> 0.011674591
A9: 180 | B9: 14 | V9: 210 | W9: =_xlfn.NORM.DIST(V9,Sheet4!$J$2,Sheet4!$J$3,FALSE) -> 0.013066075
A10: 190 | B10: 30 | V10: 220 | W10: =_xlfn.NORM.DIST(V10,Sheet4!$J$2,Sheet4!$J$3,FALSE) -> 0.013093489
A11: 200 | B11: 23 | V11: 230 | W11: =_xlfn.NORM.DIST(V11,Sheet4!$J$2,Sheet4!$J$3,FALSE) -> 0.011748227
A12: 210 | B12: 47 | V12: 240 | W12: =_xlfn.NORM.DIST(V12,Sheet4!$J$2,Sheet4!$J$3,FALSE) -> 0.0094383486
A13: 220 | B13: 45 | V13: 250 | W13: =_xlfn.NORM.DIST(V13,Sheet4!$J$2,Sheet4!$J$3,FALSE) -> 0.0067893225
A14: 230 | B14: 32 | V14: 260 | W14: =_xlfn.NORM.DIST(V14,Sheet4!$J$2,Sheet4!$J$3,FALSE) -> 0.0043728401
A15: 240 | B15: 21 | V15: 270 | W15: =_xlfn.NORM.DIST(V15,Sheet4!$J$2,Sheet4!$J$3,FALSE) -> 0.0025217818
A16: 250 | B16: 20 | V16: 280 | W16: =_xlfn.NORM.DIST(V16,Sheet4!$J$2,Sheet4!$J$3,FALSE) -> 0.0013021414
... A18: 270 | B18: 17 | V18: 300 | W18: =_xlfn.NORM.DIST(V18,Sheet4!$J$2,Sheet4!$J$3,FALSE) -> 0.00024921811
A19: 280 | B19: 2
A20: 290 | B20: 1
A21: 300 | B21: 1
A22: Grand Total | B22: 290

Sheet Sheet4
A1: date | B1: score | C1: model | D1: cutoff | E1: loss | F1: rounded | G1: fd_id
A2: 42019 | B2: 235.4 | C2: EN | D2: 0 | E2: l2 | F2: =ROUND(B2/10,0)*10 -> 240 | I2: 0 | J2: =AVERAGE(B:B) -> 215.18966
A3: 42020 | B3: 170.9 | C3: EN | D3: 0 | E3: l2 | F3: =ROUND(B3/10,0)*10 -> 170 | I3: 0 | J3: =_xlfn.STDEV.S(B:B) -> 30.081675
A4: 42020 | B4: 219.7 | C4: EN | D4: 0 | E4: l2 | F4: =ROUND(B4/10,0)*10 -> 220 | I4: 0
A5: 42021 | B5: 240.4 | C5: EN | D5: 0 | E5: l2 | F5: =ROUND(B5/10,0)*10 -> 240 | I5: 0
A6: 42022 | B6: 206.4 | C6: EN | D6: 0 | E6: l2 | F6: =ROUND(B6/10,0)*10 -> 210 | I6: 0
A7: 42023 | B7: 256.2 | C7: EN | D7: 0 | E7: l2 | F7: =ROUND(B7/10,0)*10 -> 260 | I7: 0
A8: 42024 | B8: 225.5 | C8: EN | D8: 0 | E8: l2 | F8: =ROUND(B8/10,0)*10 -> 230 | I8: 0
A9: 42024 | B9: 247.5 | C9: EN | D9: 0 | E9: l2 | F9: =ROUND(B9/10,0)*10 -> 250 | I9: 0
A10: 42026 | B10: 189.9 | C10: EN | D10: 0 | E10: l2 | F10: =ROUND(B10/10,0)*10 -> 190 | I10: 0
A11: 42027 | B11: 281.3 | C11: EN | D11: 0 | E11: l2 | F11: =ROUND(B11/10,0)*10 -> 280 | I11: 0
A12: 41664 | B12: 213.4 | C12: EN | D12: 0 | E12: l2 | F12: =ROUND(B12/10,0)*10 -> 210 | I12: 0
A13: 41664 | B13: 214.8 | C13: EN | D13: 0 | E13: l2 | F13: =ROUND(B13/10,0)*10 -> 210 | I13: 0
A14: 41667 | B14: 207.2 | C14: EN | D14: 0 | E14: l2 | F14: =ROUND(B14/10,0)*10 -> 210 | I14: 0
A15: 41666 | B15: 162.4 | C15: EN | D15: 0 | E15: l2 | F15: =ROUND(B15/10,0)*10 -> 160 | I15: 0
... A81: 42034 | B81: 173.7 | C81: SVR | D81: 8 | E81: l1 | F81: =ROUND(B81/10,0)*10 -> 170 | I81: 0
A82: 42035 | B82: 191.5 | C82: EN | D82: 8 | E82: l2 | F82: =ROUND(B82/10,0)*10 -> 190 | G82: S128558921 | I82: 0
A83: 42035 | B83: 178.6 | C83: EN | D83: 8 | E83: l1 | F83: =ROUND(B83/10,0)*10 -> 180 | G83: S128556021 | I83: 0
A84: 42035 | B84: 178.7 | C84: EN | D84: 0 | E84: l1 | F84: =ROUND(B84/10,0)*10 -> 180 | G84: S128560946 | I84: 0
A85: 42035 | B85: 191.5 | C85: EN | D85: 0 | E85: l2 | F85: =ROUND(B85/10,0)*10 -> 190 | G85: S128556021 | I85: 0
A86: 42035 | B86: 217.7 | C86: SVR | D86: 8 | E86: l1 | F86: =ROUND(B86/10,0)*10 -> 220 | G86: S128562122 | I86: 0
A87: 42035 | B87: 219.3 | C87: EN | D87: 8 | E87: l2 | F87: =ROUND(B87/10,0)*10 -> 220 | G87: S128690900 | I87: 0
A88: 42035 | B88: 205.4 | C88: EN | D88: 8 | E88: l1 | F88: =ROUND(B88/10,0)*10 -> 210 | G88: S128692562 | I88: 0
A89: 42035 | B89: 185.9 | C89: EN | D89: 0 | E89: l1 | F89: =ROUND(B89/10,0)*10 -> 190 | G89: S128691698 | I89: 0
A90: 42035 | B90: 179.4 | C90: EN | D90: 0 | E90: l2 | F90: =ROUND(B90/10,0)*10 -> 180 | G90: S128690094 | I90: 0
A91: 42035 | B91: 212.8 | C91: SVR | D91: 8 | E91: l1 | F91: =ROUND(B91/10,0)*10 -> 210 | G91: S128693346 | I91: 0
A92: 42036 | B92: 254.5 | C92: EN | D92: 0 | E92: l2 | F92: =ROUND(B92/10,0)*10 -> 250 | G92: S129181179 | I92: 0
A93: 42036 | B93: 254.5 | C93: EN | D93: 8 | E93: l2 | F93: =ROUND(B93/10,0)*10 -> 250 | G93: S129181179 | I93: 0
... A200: 42056 | B200: 231.9 | C200: NN | D200: 8 | E200: l2 | F200: =ROUND(B200/10,0)*10 -> 230 | G200: S138058281 | I200: 0
A201: 42057 | B201: 207.9 | C201: EN | D201: 0 | E201: l2 | F201: =ROUND(B201/10,0)*10 -> 210 | G201: S138661867
A202: 42057 | B202: 188.7 | C202: EN | D202: 8 | E202: l2 | F202: =ROUND(B202/10,0)*10 -> 190 | G202: S138662412
A203: 42057 | B203: 205.3 | C203: SVR | D203: 8 | E203: l1 | F203: =ROUND(B203/10,0)*10 -> 210 | G203: S138662833
A204: 42057 | B204: 189 | C204: NN | D204: 8 | E204: l2 | F204: =ROUND(B204/10,0)*10 -> 190 | G204: S138663125
A205: 42058 | B205: 200.7 | C205: EN | D205: 0 | E205: l2 | F205: =ROUND(B205/10,0)*10 -> 200 | G205: S139226573
A206: 42058 | B206: 200.7 | C206: EN | D206: 8 | E206: l2 | F206: =ROUND(B206/10,0)*10 -> 200 | G206: S139226573
A207: 42058 | B207: 158.1 | C207: SVR | D207: 8 | E207: l1 | F207: =ROUND(B207/10,0)*10 -> 160 | G207: S139227064
A208: 42058 | B208: 212.7 | C208: NN | D208: 8 | E208: l2 | F208: =ROUND(B208/10,0)*10 -> 210 | G208: S139227520
A209: 42059 | B209: 218.3 | C209: EN | D209: 0 | E209: l2 | F209: =ROUND(B209/10,0)*10 -> 220 | G209: S139786602
A210: 42059 | B210: 231.9 | C210: EN | D210: 8 | E210: l2 | F210: =ROUND(B210/10,0)*10 -> 230 | G210: S139787499
A211: 42059 | B211: 246.3 | C211: SVR | D211: 8 | E211: l1 | F211: =ROUND(B211/10,0)*10 -> 250 | G211: S139787999
...
